tests/32_threads/sample_83.in
32
o
27 B 102 1 1367 959
20 B 104 7 1778 12
7 S 105 0 1838 921
15 S 110 5 1926 570
11 B 111 7 1525 13
26 S 114 7 1166 968
31 B 115 4 1220 927
4 S 116 8 1275 663
11 C 111
25 B 120 9 1226 989
14 S 121 8 1275 771
10 S 123 8 1273 68
2 B 124 0 1322 920
21 B 125 0 1962 675
28 B 128 0 1648 824
15 S 129 7 1230 88
24 B 130 7 1645 905
23 B 131 4 1649 544
17 B 132 3 1580 244
21 B 133 1 1293 190
4 C 116
26 B 135 4 1442 737
24 S 136 6 1283 53
16 B 138 6 1934 352
19 S 139 7 1165 139
15 C 129
26 B 141 6 1107 718
1 S 142 8 1341 173
16 B 143 7 1877 54
19 C 139
27 B 145 9 1923 573
24 S 146 2 1855 711
6 S 147 2 1108 965
30 S 148 4 1875 79
14 B 149 1 1794 788
10 C 123
26 B 151 9 1947 442
4 S 152 8 1607 977
23 B 153 2 1433 349
3 B 154 8 1305 857
19 C 139
5 S 157 0 1313 488
8 S 158 0 1485 721
6 C 147
11 C 111
5 S 164 5 1403 348
11 B 165 1 1129 451
29 S 166 4 1007 951
11 C 165
30 B 168 5 1028 797
11 S 169 5 1162 883
27 S 170 9 1119 759
16 S 171 6 1899 173
25 B 172 1 1071 649
7 C 105
6 B 174 5 1582 39
6 C 174
22 B 176 0 1856 233
5 C 164
7 B 178 8 1380 981
5 C 164
2 S 180 0 1697 613
1 B 181 3 1805 190
27 B 182 7 1025 466
4 C 152
17 C 132
24 C 136
11 C 111
18 S 187 5 1909 466
12 S 188 6 1769 609
5 C 164
21 B 190 9 1887 412
25 C 172
24 S 193 9 1000 150
3 B 194 1 1785 307
16 C 138
8 B 196 5 1587 451
10 C 123
31 B 199 6 1384 864
22 B 200 6 1228 316
4 B 202 4 1835 745
3 S 203 9 1469 885
22 S 204 6 1358 224
15 C 129
25 C 120
2 S 207 6 1492 89
22 B 208 4 1986 734
2 C 124
1 B 210 8 1675 467
20 C 104
8 B 212 2 1913 116
17 S 213 0 1208 516
23 B 214 8 1456 201
2 C 180
24 S 216 6 1862 405
18 C 187
17 C 213
12 S 220 7 1251 543
0 B 221 9 1065 807
10 S 222 1 1083 451
21 C 190
25 B 224 2 1154 887
24 C 193
8 C 196
15 B 227 6 1530 885
21 B 228 6 1979 648
15 B 229 1 1296 541
12 C 188
14 B 231 3 1661 193
13 S 232 7 1333 919
11 B 233 1 1276 533
6 C 174
2 B 235 7 1931 110
30 C 168
19 B 237 0 1645 225
25 B 238 9 1550 722
9 S 239 1 1426 565
30 C 148
22 B 241 3 1077 1000
6 C 174
25 B 243 5 1520 903
28 B 244 6 1146 317
16 S 245 8 1107 877
4 B 246 5 1463 32
24 C 130
20 B 248 6 1412 426
25 B 249 9 1200 888
7 C 178
23 C 214
5 S 252 5 1319 739
6 C 147
23 B 254 4 1499 491
11 S 255 5 1625 517
7 B 256 0 1201 902
17 B 257 7 1386 217
27 C 145
31 B 259 5 1045 276
4 B 260 4 1122 575
13 B 261 1 1862 216
4 S 262 9 1615 177
22 C 204
14 C 231
22 S 265 3 1897 638
21 B 266 9 1917 584
24 C 146
21 C 133
11 C 169
17 B 270 6 1233 240
1 S 271 1 1238 767
29 C 166
26 B 273 5 1203 794
12 B 274 8 1150 760
27 B 275 0 1320 373
16 C 138
15 S 277 7 1759 152
10 C 222
22 S 279 5 1405 934
6 B 280 7 1408 150
16 C 143
25 S 282 5 1899 406
13 C 261
26 S 284 5 1498 689
25 B 285 7 1115 241
5 C 252
11 S 287 2 1378 370
23 B 288 9 1199 362
30 S 289 5 1772 18
24 C 146
5 S 291 2 1773 772
6 C 280
26 S 293 9 1686 784
9 B 294 7 1185 113
31 C 115
30 S 296 7 1043 962
7 S 297 5 1764 33
28 C 128
24 C 130
4 B 300 7 1981 449
18 B 301 0 1169 862
20 C 248
15 C 227
7 S 304 5 1750 435
14 B 305 5 1086 975
7 B 306 1 1139 373
13 S 307 0 1944 830
25 C 238
25 S 309 5 1538 59
9 C 294
8 B 311 8 1797 932
29 C 166
22 B 313 8 1962 524
11 C 255
29 C 166
11 S 316 7 1603 264
29 B 317 5 1017 138
22 C 279
24 C 146
7 B 320 4 1050 268
20 C 248
28 B 322 4 1405 688
9 S 323 9 1075 663
4 C 300
11 S 325 6 1375 356
10 B 326 1 1068 444
22 C 176
0 S 328 4 1109 989
9 C 294
27 C 145
23 B 331 1 1038 597
18 S 332 9 1053 135
8 B 333 3 1797 784
3 C 203
0 B 335 5 1762 576
5 B 336 1 1134 100
15 C 227
22 C 208
8 C 158
3 B 340 1 1848 881
15 B 341 3 1522 467
5 C 291
5 C 291
17 S 344 3 1009 768
15 S 345 5 1394 226
28 B 346 5 1551 526
1 B 347 3 1362 684
18 C 187
19 B 349 3 1544 436
16 B 350 8 1776 928
7 S 351 9 1780 118
13 C 261
3 S 353 4 1238 790
11 B 354 1 1561 448
2 S 355 8 1176 614
24 S 356 3 1944 84
26 S 357 3 1560 232
29 S 358 1 1134 144
5 C 291
25 C 238
8 C 196
14 B 362 7 1359 469
12 C 220
11 S 364 7 1548 227
29 B 365 4 1630 712
26 C 293
1 B 367 9 1097 915
30 B 368 2 1298 489
14 S 369 6 1277 150
9 C 323
22 B 371 9 1496 840
15 S 372 7 1439 386
23 S 373 6 1005 702
19 B 374 1 1432 381
27 C 275
29 S 376 2 1916 812
30 C 148
2 B 378 2 1435 876
8 C 196
18 S 380 6 1880 107
31 S 381 7 1381 496
21 B 382 4 1722 640
13 S 383 0 1870 775
3 B 384 8 1854 384
10 B 385 6 1703 153
22 S 386 1 1118 247
28 S 387 8 1102 419
27 B 388 5 1971 783
19 B 389 9 1524 600
0 B 390 0 1601 109
0 C 328
1 C 181
15 B 393 8 1780 529
31 S 394 5 1263 967
15 S 395 5 1614 501
14 B 396 7 1684 13
23 B 397 2 1957 583
6 B 398 0 1999 878
8 C 158
14 S 400 8 1349 888
23 B 401 8 1666 10
9 B 402 9 1052 966
14 B 403 3 1546 737
3 B 404 8 1219 400
11 C 233
16 B 406 1 1922 180
18 C 380
13 B 408 8 1371 670
17 B 409 9 1092 52
13 S 410 2 1617 166
25 C 238
0 B 412 8 1700 155
3 S 413 1 1596 706
12 C 188
29 S 415 8 1904 247
20 C 248
5 C 336
15 B 418 1 1466 94
11 B 419 3 1915 433
29 C 358
26 C 273
14 S 422 1 1861 121
31 S 423 6 1057 528
21 S 424 5 1275 356
16 C 245
21 C 125
29 C 415
20 S 428 3 1655 580
17 B 429 3 1080 318
8 C 333
18 S 431 0 1276 492
16 S 432 7 1141 636
26 S 433 1 1335 285
2 S 434 9 1857 35
5 C 291
17 C 270
22 C 241
13 S 438 4 1566 439
10 B 439 8 1529 111
2 S 440 8 1378 322
14 C 231
2 B 442 2 1072 86
22 S 443 5 1370 905
26 B 444 6 1258 594
7 B 445 7 1483 386
4 B 446 3 1712 970
6 B 447 4 1707 449
11 C 325
26 B 449 7 1846 166
15 B 450 4 1952 724
25 C 282
31 B 452 3 1438 481
8 B 453 0 1572 53
13 B 454 0 1038 754
11 C 255
28 B 456 9 1074 162
6 C 398
27 S 458 6 1891 215
6 S 459 0 1307 205
23 B 460 6 1815 799
11 C 165
23 C 288
23 S 463 3 1482 142
21 C 228
27 C 182
17 S 466 1 1837 229
20 B 467 8 1900 453
18 B 468 4 1347 100
16 C 245
17 S 470 5 1647 650
29 S 471 1 1078 657
21 B 472 3 1843 646
0 S 473 7 1414 976
9 C 402
12 B 475 2 1142 156
12 B 476 6 1034 134
15 S 477 0 1375 970
25 C 238
13 S 479 9 1902 180
20 C 428
6 B 481 7 1211 986
21 C 228
24 S 483 2 1312 238
16 B 484 0 1280 548
21 B 485 1 1990 788
1 C 181
3 B 487 5 1733 559
20 B 488 9 1133 220
12 C 475
19 B 490 4 1392 28
0 S 491 3 1270 18
10 C 326
1 B 493 6 1094 548
1 S 494 1 1518 854
5 B 495 8 1040 142
2 C 434
4 S 497 6 1739 831
9 B 498 9 1401 930
3 C 194
2 S 500 6 1918 19
29 B 501 4 1171 914
19 C 490
18 B 503 4 1279 358
8 S 504 7 1163 327
21 C 133
17 S 506 5 1722 821
3 C 487
24 C 146
20 S 509 5 1368 723
26 C 273
2 C 434
21 B 512 7 1257 132
20 S 513 9 1754 56
2 B 514 1 1421 337
0 C 412
1 B 516 9 1075 421
6 C 447
15 S 518 7 1130 769
11 S 519 6 1302 682
28 S 520 5 1720 966
21 S 521 7 1112 426
12 S 522 3 1191 709
28 S 523 9 1966 688
1 S 524 6 1233 599
5 C 336
30 S 526 1 1069 363
0 S 527 4 1219 981
29 C 376
6 S 529 8 1667 427
2 S 530 1 1019 141
20 S 531 3 1150 755
28 B 532 1 1457 441
27 C 145
11 S 534 9 1878 828
23 C 397
21 C 382
30 S 537 0 1880 969
23 B 538 1 1155 189
26 C 273
20 B 540 1 1869 569
23 S 541 7 1634 749
24 S 542 6 1449 615
2 S 543 2 1195 391
17 S 544 4 1748 32
17 C 506
12 S 546 1 1613 653
6 C 529
15 C 372
3 C 487
7 C 178
8 S 551 6 1957 29
14 S 552 6 1965 514
24 S 553 2 1553 935
26 S 554 9 1481 175
28 S 555 1 1781 931
24 S 556 2 1370 464
4 S 557 1 1140 882
20 B 558 9 1829 81
21 C 472
31 S 560 2 1227 371
0 S 561 7 1428 856
13 C 261
4 C 260
19 S 564 9 1678 972
7 S 565 2 1737 285
8 C 158
8 B 567 4 1123 662
9 B 568 9 1107 287
11 B 569 6 1574 196
26 C 114
2 B 571 0 1952 891
25 B 572 3 1572 941
28 B 573 4 1198 914
4 C 260
19 C 389
17 S 576 1 1648 452
13 B 577 0 1322 294
22 C 204
24 C 136
22 C 371
3 C 384
8 C 212
21 S 583 2 1322 808
28 S 584 6 1570 742
9 C 239
4 B 586 9 1097 82
7 C 304
18 C 332
11 B 589 8 1531 126
6 C 280
25 C 282
13 S 592 5 1459 865
31 C 259
1 B 594 9 1076 434
16 S 595 8 1663 591
22 B 596 1 1563 237
13 S 597 7 1123 746
3 B 598 6 1624 670
27 C 458
23 S 600 3 1756 215
20 S 601 7 1786 279
10 C 326
30 B 603 3 1815 44
15 S 604 8 1157 251
25 B 605 3 1261 995
16 S 606 3 1732 646
17 S 607 6 1452 217
2 C 355
24 S 609 7 1877 490
11 B 610 1 1949 555
9 S 611 3 1752 645
8 B 612 7 1522 210
26 C 141
0 B 614 9 1735 664
8 C 311
1 S 616 0 1624 299
26 B 617 7 1534 231
22 B 618 0 1869 242
21 B 619 3 1067 812
16 S 620 5 1019 915
6 B 621 2 1829 455
28 S 622 4 1741 628
18 B 623 5 1184 320
