tests/32_threads/sample_84.in
32
o
11 S 101 9 1021 949
9 S 102 7 1497 347
1 B 103 4 1473 747
20 B 105 1 1458 426
18 S 106 5 1557 62
10 S 107 4 1712 538
20 B 108 8 1089 600
5 B 109 7 1883 129
23 B 110 4 1956 683
29 B 111 7 1455 124
11 S 112 1 1469 702
18 S 113 1 1160 595
7 S 114 3 1781 619
11 S 115 4 1485 924
12 S 117 0 1150 753
23 B 118 5 1046 502
26 S 119 2 1368 416
18 C 106
1 S 121 8 1981 316
29 B 122 7 1066 663
19 S 124 0 1109 94
21 B 126 5 1917 319
5 C 109
30 S 128 3 1462 190
23 S 131 0 1262 46
8 S 132 5 1189 507
16 B 133 1 1790 790
23 C 110
9 S 135 8 1807 636
11 C 115
8 B 137 5 1529 529
10 S 138 1 1071 536
1 B 140 3 1137 544
21 S 141 3 1416 498
17 B 142 7 1196 41
5 C 109
11 C 115
8 S 145 2 1889 703
2 S 146 5 1739 131
11 C 101
12 C 117
31 S 149 4 1738 259
9 B 151 8 1102 244
29 S 152 2 1555 850
12 B 154 6 1193 585
19 S 155 1 1762 675
14 S 156 4 1958 990
0 S 158 2 1317 999
28 S 159 1 1630 115
3 S 160 0 1887 426
20 S 161 9 1004 410
16 C 133
8 B 163 9 1887 134
26 B 164 6 1385 25
31 C 149
14 S 166 2 1570 745
8 S 167 9 1933 266
2 C 146
26 C 164
18 S 170 7 1753 495
3 C 160
9 C 135
5 B 173 2 1346 119
8 C 163
21 S 175 1 1860 503
7 B 176 4 1268 150
18 C 106
21 S 178 2 1110 577
12 S 179 9 1489 897
27 S 180 2 1780 346
29 B 181 4 1534 413
12 S 182 5 1494 137
25 S 183 6 1088 545
25 B 184 3 1244 498
0 B 185 5 1829 172
21 B 186 0 1070 394
25 C 184
14 C 156
23 B 189 3 1576 682
12 S 190 6 1028 321
18 B 191 4 1513 629
2 S 193 2 1705 159
21 C 175
12 C 117
12 S 196 0 1384 287
30 B 197 9 1083 229
20 B 198 1 1709 616
17 C 142
31 B 200 6 1799 845
30 B 201 4 1561 664
12 C 190
30 B 203 8 1905 594
14 C 166
7 B 205 1 1914 23
8 C 163
23 S 207 8 1647 800
17 B 208 5 1491 154
5 C 109
3 B 210 5 1169 988
4 B 211 4 1223 938
16 B 212 7 1598 341
0 B 213 1 1416 917
3 C 210
27 S 215 6 1578 534
3 S 216 3 1542 50
24 S 217 9 1583 843
8 C 145
0 B 219 6 1190 179
17 B 220 6 1270 917
26 C 119
21 B 222 0 1677 771
18 S 224 1 1018 777
12 S 225 6 1852 931
21 B 226 1 1136 59
17 C 208
5 C 109
14 S 229 3 1509 990
15 B 230 0 1851 957
4 C 211
5 B 232 4 1841 767
1 B 233 5 1183 531
7 C 114
14 C 229
10 C 138
21 S 237 0 1517 407
15 B 238 9 1912 246
24 C 217
13 B 240 4 1084 95
19 C 124
26 B 242 1 1284 119
0 S 243 3 1728 910
19 B 244 0 1515 553
11 B 245 8 1670 613
11 B 246 3 1838 888
15 B 247 2 1460 659
11 C 246
3 S 249 4 1525 625
12 C 190
8 B 251 1 1185 316
1 C 233
14 B 253 1 1352 960
11 C 112
25 C 184
27 S 256 0 1612 107
26 S 257 5 1920 667
11 C 115
30 B 259 0 1810 57
3 S 260 0 1498 151
18 C 106
22 S 262 5 1039 621
31 S 263 4 1166 108
10 S 264 0 1754 479
3 C 216
8 B 266 2 1664 148
24 B 267 5 1799 227
5 C 173
30 C 197
9 C 135
26 S 271 2 1809 392
11 B 272 7 1881 169
29 S 273 2 1071 845
30 B 274 9 1565 725
29 S 275 4 1587 306
22 C 262
20 S 277 4 1963 62
26 C 271
12 C 179
22 C 262
4 C 211
0 C 158
16 C 212
3 B 284 5 1574 572
20 S 285 4 1275 709
7 S 286 2 1462 658
1 B 287 1 1575 171
0 B 288 2 1808 525
18 C 170
3 S 290 0 1639 890
22 C 262
31 C 263
13 C 240
9 C 151
18 S 295 6 1984 191
19 S 296 0 1210 373
7 S 297 6 1242 786
14 S 298 6 1766 674
22 C 262
31 B 300 2 1267 148
25 S 301 9 1338 982
8 C 145
24 C 267
30 S 304 3 1284 880
24 B 305 4 1881 844
0 S 306 2 1290 774
27 S 307 5 1552 545
26 B 308 2 1145 219
1 B 309 3 1075 492
26 S 310 9 1269 919
9 C 102
21 B 312 3 1985 894
10 C 264
4 B 314 6 1656 335
1 S 315 3 1649 405
22 S 316 8 1101 531
30 S 317 0 1059 458
11 C 112
13 B 319 1 1380 628
5 B 320 9 1058 754
29 S 321 4 1443 262
15 C 247
24 S 323 6 1912 552
10 C 138
5 B 325 2 1762 550
13 B 326 7 1014 417
3 B 327 5 1474 284
23 C 131
21 B 329 8 1270 74
7 S 330 1 1220 362
10 C 264
8 S 332 4 1207 573
21 B 333 3 1206 252
13 C 240
8 S 335 6 1520 829
31 B 336 8 1835 358
20 S 337 7 1248 83
13 B 338 6 1795 671
5 S 339 2 1681 374
12 C 196
24 C 217
3 S 342 6 1306 746
0 S 343 7 1994 874
4 B 344 8 1343 65
20 S 345 5 1154 577
28 B 346 9 1646 506
18 C 191
7 B 348 2 1286 679
28 C 346
5 B 350 5 1814 659
18 B 351 5 1996 90
10 B 352 7 1739 184
26 S 353 5 1233 515
25 C 184
30 C 317
22 S 356 4 1793 589
28 B 357 1 1075 672
1 B 358 0 1650 876
5 C 325
12 B 360 3 1035 155
15 B 361 5 1840 398
23 S 362 1 1946 847
11 S 363 9 1580 872
27 C 180
27 C 307
2 B 366 2 1797 612
6 S 367 0 1303 457
6 C 367
24 C 267
16 S 370 4 1769 628
4 B 371 1 1387 107
3 C 249
11 C 272
30 C 274
10 C 352
10 S 376 4 1454 180
4 C 344
30 C 317
1 B 379 8 1324 78
23 B 380 9 1001 794
20 S 381 6 1293 983
5 B 382 3 1779 987
27 C 215
20 C 105
23 C 131
6 C 367
8 C 163
19 S 388 6 1475 193
14 S 389 1 1449 573
7 S 390 5 1841 888
27 S 391 1 1544 709
23 C 131
24 S 393 5 1528 393
17 B 394 5 1689 233
8 C 137
14 B 396 0 1208 779
3 B 397 1 1233 166
30 C 259
20 S 399 2 1708 796
23 S 400 0 1114 992
18 C 295
21 B 402 0 1165 562
1 S 403 7 1148 98
5 B 404 9 1712 588
5 B 405 7 1034 338
21 C 178
28 B 407 6 1937 63
25 S 408 3 1791 719
9 C 102
8 S 410 9 1850 513
20 S 411 1 1587 917
31 B 412 0 1978 560
23 S 413 0 1494 184
20 B 414 8 1966 636
29 B 415 3 1446 932
12 C 179
26 B 417 8 1476 316
30 B 418 6 1757 30
25 C 408
9 B 420 8 1997 349
24 B 421 9 1925 341
6 S 422 6 1995 374
20 S 423 4 1810 454
24 C 267
20 B 425 8 1638 697
18 B 426 4 1598 70
17 B 427 1 1670 79
31 B 428 5 1507 726
31 B 429 2 1792 315
7 B 430 7 1150 123
18 S 431 5 1861 100
29 C 152
9 B 433 6 1942 335
23 C 413
15 S 435 9 1095 684
7 S 436 3 1013 320
26 S 437 4 1376 923
21 S 438 5 1623 368
19 B 439 0 1421 205
4 B 440 7 1947 834
19 S 441 5 1767 315
23 C 118
20 C 381
15 C 361
31 B 445 9 1869 553
20 S 446 6 1957 294
24 C 421
21 C 312
18 C 295
1 B 450 2 1004 749
22 C 356
26 C 417
9 S 453 3 1276 167
0 C 219
10 B 455 0 1515 754
4 B 456 3 1428 112
15 C 435
1 C 103
21 B 459 3 1180 653
28 S 460 6 1537 408
8 C 145
8 C 266
27 S 463 2 1779 624
19 C 296
29 S 465 4 1600 1000
1 B 466 0 1934 44
29 B 467 4 1807 659
7 B 468 0 1000 727
31 C 200
21 C 178
25 C 183
4 B 472 7 1894 446
15 C 361
19 B 474 2 1921 547
25 S 475 3 1961 1000
7 B 476 2 1659 761
20 C 411
30 B 478 3 1630 819
30 B 479 8 1382 481
15 B 480 7 1561 836
7 B 481 9 1729 609
26 C 242
24 S 483 6 1920 813
21 C 438
6 C 367
8 B 486 2 1054 18
18 S 487 5 1588 894
29 B 488 5 1021 322
21 S 489 5 1611 822
0 C 219
8 S 491 0 1263 972
2 S 492 1 1076 437
9 S 493 8 1772 111
23 S 494 5 1280 969
1 C 450
28 B 496 9 1085 399
14 B 497 9 1411 138
23 C 189
10 S 499 4 1022 730
22 C 262
22 C 356
9 B 502 3 1464 186
19 B 503 9 1648 838
14 C 253
31 B 505 5 1448 433
15 S 506 9 1434 526
14 C 156
11 B 508 6 1569 70
28 S 509 0 1789 996
10 S 510 0 1781 53
21 B 511 2 1692 364
10 C 499
14 S 513 5 1386 961
3 B 514 9 1677 861
24 S 515 3 1587 204
29 S 516 8 1216 866
22 B 517 7 1546 355
1 B 518 1 1812 165
20 B 519 5 1244 67
24 S 520 5 1645 641
2 C 492
25 S 522 9 1798 341
28 B 523 2 1040 577
3 C 284
5 C 232
2 S 526 5 1072 770
7 C 481
21 S 528 5 1845 493
27 B 529 0 1268 377
24 C 421
5 S 531 6 1328 486
10 B 532 8 1383 901
16 S 533 2 1467 555
8 B 534 8 1309 925
28 S 535 7 1671 593
28 B 536 0 1717 887
29 S 537 7 1265 973
15 S 538 1 1174 342
19 C 155
16 C 133
28 S 541 0 1764 803
21 C 511
22 C 316
0 S 544 7 1097 730
13 B 545 8 1395 680
25 C 475
3 C 216
21 S 548 1 1421 13
3 C 284
12 B 550 3 1436 66
19 S 551 2 1754 50
1 C 379
14 S 553 5 1583 864
6 S 554 4 1237 202
7 C 390
3 B 556 6 1789 870
8 C 145
2 C 146
5 S 559 0 1594 134
19 B 560 0 1074 522
8 B 561 6 1779 605
18 B 562 4 1558 675
12 C 182
10 S 564 9 1166 385
0 B 565 3 1408 857
22 B 566 0 1943 738
18 C 351
20 B 568 5 1883 13
15 C 480
31 C 429
13 B 571 0 1901 281
12 C 182
25 S 573 1 1401 361
18 B 574 5 1189 305
10 B 575 3 1217 572
6 B 576 0 1138 421
27 S 577 7 1310 273
24 S 578 9 1987 443
24 S 579 2 1752 466
27 S 580 4 1657 771
23 C 131
5 C 404
17 C 208
14 C 166
16 C 533
12 C 154
27 C 577
15 C 480
5 S 589 8 1800 746
7 B 590 6 1772 808
5 C 339
10 S 592 2 1155 823
30 S 593 3 1431 931
14 B 594 7 1270 465
9 S 595 8 1055 58
1 S 596 4 1487 208
0 S 597 8 1319 485
30 S 598 7 1961 633
26 C 353
16 C 370
0 S 601 3 1308 918
30 S 602 7 1456 367
3 S 603 7 1525 414
21 C 237
3 S 605 0 1944 164
2 S 606 0 1087 951
26 B 607 7 1733 921
13 C 338
30 C 418
12 C 550
14 B 611 9 1514 267
23 B 612 3 1532 675
17 B 613 7 1457 29
27 S 614 3 1570 676
10 B 615 1 1545 776
